Workbook

Sheet Resumen
A1: RESUMEN MENSUAL - VOLQUETAS | B1: RESUMEN MENSUAL - VOLQUETAS | C1: RESUMEN MENSUAL - VOLQUETAS | D1: RESUMEN MENSUAL - VOLQUETAS | E1: RESUMEN MENSUAL - VOLQUETAS | F1: RESUMEN MENSUAL - VOLQUETAS | G1: RESUMEN MENSUAL - VOLQUETAS | H1: RESUMEN MENSUAL - VOLQUETAS | I1: RESUMEN MENSUAL - VOLQUETAS | J1: RESUMEN MENSUAL - VOLQUETAS
A2: RESUMEN MENSUAL - VOLQUETAS | B2: RESUMEN MENSUAL - VOLQUETAS | C2: RESUMEN MENSUAL - VOLQUETAS | D2: RESUMEN MENSUAL - VOLQUETAS | E2: RESUMEN MENSUAL - VOLQUETAS | F2: RESUMEN MENSUAL - VOLQUETAS | G2: RESUMEN MENSUAL - VOLQUETAS | H2: RESUMEN MENSUAL - VOLQUETAS | I2: RESUMEN MENSUAL - VOLQUETAS | J2: RESUMEN MENSUAL - VOLQUETAS
A3: ="Periodo: "&CHOOSE(Configuracion!$B$8,"Enero","Febrero","Marzo","Abril","Mayo","Junio","Julio","Agosto","Septiembre","Octubre","Noviembre","Diciembre")&" "&Configuracion!$B$7 -> Periodo: Junio 2026
A5: META MENSUAL | B5: META MENSUAL | D5: VIAJES REALIZADOS | E5: VIAJES REALIZADOS | G5: VIAJES PENDIENTES | H5: VIAJES PENDIENTES | I5: AVANCE DE META | J5: AVANCE DE META
A6: =SUM('Registro diario'!$J$7:$J$37) -> 360 | D6: =SUM('Registro diario'!$I$7:$I$37) -> 81 | G6: =MAX(0,A6-D6) -> 279 | I6: =IF(A6=0,0,D6/A6) -> 0.225
A9: VALOR BRUTO | B9: VALOR BRUTO | D9: MI GANANCIA (22%) | E9: MI GANANCIA (22%) | G9: DIAS TRABAJADOS | H9: DIAS TRABAJADOS | I9: PROMEDIO POR DIA | J9: PROMEDIO POR DIA
A10: =SUM('Registro diario'!$M$7:$M$37) -> 2406000 | D10: =SUM('Registro diario'!$N$7:$N$37) -> 529320 | G10: =COUNTIF('Registro diario'!$I$7:$I$37,">0") -> 6 | I10: =IF(G10=0,0,D6/G10) -> 13.5
A13: RESUMEN POR SEMANA | B13: RESUMEN POR SEMANA | C13: RESUMEN POR SEMANA | D13: RESUMEN POR SEMANA | E13: RESUMEN POR SEMANA | F13: RESUMEN POR SEMANA | G13: RESUMEN POR SEMANA
A14: Semana | B14: Meta | C14: Realizados | D14: Pendientes | E14: % Cumplido | F14: Valor bruto | G14: Mi 22% | I14: Semana | J14: Meta | K14: Realizados
A15: Semana 1 | B15: =SUMIF('Registro diario'!$C$7:$C$37,1,'Registro diario'!$J$7:$J$37) -> 80 | C15: =SUMIF('Registro diario'!$C$7:$C$37,1,'Registro diario'!$I$7:$I$37) -> 0 | D15: =MAX(0,B15-C15) -> 80 | E15: =IF(B15=0,"",C15/B15) -> 0 | F15: =SUMIF('Registro diario'!$C$7:$C$37,1,'Registro diario'!$M$7:$M$37) -> 0 | G15: =SUMIF('Registro diario'!$C$7:$C$37,1,'Registro diario'!$N$7:$N$37) -> 0 | I15: S1 | J15: =B15 -> 80 | K15: =C15 -> 0
A16: Semana 2 | B16: =SUMIF('Registro diario'!$C$7:$C$37,2,'Registro diario'!$J$7:$J$37) -> 80 | C16: =SUMIF('Registro diario'!$C$7:$C$37,2,'Registro diario'!$I$7:$I$37) -> 69 | D16: =MAX(0,B16-C16) -> 11 | E16: =IF(B16=0,"",C16/B16) -> 0.8625 | F16: =SUMIF('Registro diario'!$C$7:$C$37,2,'Registro diario'!$M$7:$M$37) -> 2166000 | G16: =SUMIF('Registro diario'!$C$7:$C$37,2,'Registro diario'!$N$7:$N$37) -> 476520 | I16: S2 | J16: =B16 -> 80 | K16: =C16 -> 69
A17: Semana 3 | B17: =SUMIF('Registro diario'!$C$7:$C$37,3,'Registro diario'!$J$7:$J$37) -> 80 | C17: =SUMIF('Registro diario'!$C$7:$C$37,3,'Registro diario'!$I$7:$I$37) -> 12 | D17: =MAX(0,B17-C17) -> 68 | E17: =IF(B17=0,"",C17/B17) -> 0.15 | F17: =SUMIF('Registro diario'!$C$7:$C$37,3,'Registro diario'!$M$7:$M$37) -> 240000 | G17: =SUMIF('Registro diario'!$C$7:$C$37,3,'Registro diario'!$N$7:$N$37) -> 52800 | I17: S3 | J17: =B17 -> 80 | K17: =C17 -> 12
A18: Semana 4 | B18: =SUMIF('Registro diario'!$C$7:$C$37,4,'Registro diario'!$J$7:$J$37) -> 80 | C18: =SUMIF('Registro diario'!$C$7:$C$37,4,'Registro diario'!$I$7:$I$37) -> 0 | D18: =MAX(0,B18-C18) -> 80 | E18: =IF(B18=0,"",C18/B18) -> 0 | F18: =SUMIF('Registro diario'!$C$7:$C$37,4,'Registro diario'!$M$7:$M$37) -> 0 | G18: =SUMIF('Registro diario'!$C$7:$C$37,4,'Registro diario'!$N$7:$N$37) -> 0 | I18: S4 | J18: =B18 -> 80 | K18: =C18 -> 0
A19: Semana 5 | B19: =SUMIF('Registro diario'!$C$7:$C$37,5,'Registro diario'!$J$7:$J$37) -> 40 | C19: =SUMIF('Registro diario'!$C$7:$C$37,5,'Registro diario'!$I$7:$I$37) -> 0 | D19: =MAX(0,B19-C19) -> 40 | E19: =IF(B19=0,"",C19/B19) -> 0 | F19: =SUMIF('Registro diario'!$C$7:$C$37,5,'Registro diario'!$M$7:$M$37) -> 0 | G19: =SUMIF('Registro diario'!$C$7:$C$37,5,'Registro diario'!$N$7:$N$37) -> 0 | I19: S5 | J19: =B19 -> 40 | K19: =C19 -> 0
A20: Semana 6 | B20: =SUMIF('Registro diario'!$C$7:$C$37,6,'Registro diario'!$J$7:$J$37) -> 0 | C20: =SUMIF('Registro diario'!$C$7:$C$37,6,'Registro diario'!$I$7:$I$37) -> 0 | D20: =MAX(0,B20-C20) -> 0 | E20: =IF(B20=0,"",C20/B20) | F20: =SUMIF('Registro diario'!$C$7:$C$37,6,'Registro diario'!$M$7:$M$37) -> 0 | G20: =SUMIF('Registro diario'!$C$7:$C$37,6,'Registro diario'!$N$7:$N$37) -> 0 | I20: S6 | J20: =B20 -> 0 | K20: =C20 -> 0
A23: DETALLE POR RUTA | B23: DETALLE POR RUTA | C23: DETALLE POR RUTA | D23: DETALLE POR RUTA | E23: DETALLE POR RUTA | F23: DETALLE POR RUTA | G23: DETALLE POR RUTA
A24: Ruta | B24: Viajes | C24: Tarifa | D24: Valor generado
A25: Rio a trituradora | B25: =SUM('Registro diario'!$D$7:$D$37) -> 67 | C25: =Configuracion!$B$14 -> 32000 | D25: =B25*C25 -> 2144000
A26: Rio a stock | B26: =SUM('Registro diario'!$E$7:$E$37) -> 3 | C26: =Configuracion!$B$15 -> 30000 | D26: =B26*C26 -> 90000
A27: Stock a trituradora | B27: =SUM('Registro diario'!$F$7:$F$37) -> 10 | C27: =Configuracion!$B$16 -> 16000 | D27: =B27*C27 -> 160000
A28: Trituradora a stock | B28: =SUM('Registro diario'!$G$7:$G$37) -> 0 | C28: =Configuracion!$B$17 -> 12000 | D28: =B28*C28 -> 0
A29: Stock a stock | B29: =SUM('Registro diario'!$H$7:$H$37) -> 1 | C29: =Configuracion!$B$18 -> 12000 | D29: =B29*C29 -> 12000
A30: TOTAL | B30: =SUM(B25:B29) -> 81 | D30: =SUM(D25:D29) -> 2406000
A32: FINANZAS DEL MES | B32: FINANZAS DEL MES | C32: FINANZAS DEL MES | D32: FINANZAS DEL MES | E32: FINANZAS DEL MES | F32: FINANZAS DEL MES | G32: FINANZAS DEL MES | H32: FINANZAS DEL MES | I32: FINANZAS DEL MES | J32: FINANZAS DEL MES
A34: GASTOS VOLQUETA | B34: GASTOS VOLQUETA | D34: APORTES RECIBIDOS | E34: APORTES RECIBIDOS | G34: RESULTADO CAJA | H34: RESULTADO CAJA | I34: GANANCIA - GASTOS | J34: GANANCIA - GASTOS
A35: =SUMIFS('Gastos volqueta'!$E$7:$E$205,'Gastos volqueta'!$B$7:$B$205,Configuracion!$B$8,'Gastos volqueta'!$I$7:$I$205,Configuracion!$B$7) -> 0 | D35: =SUMIFS('Aportes tios'!$E$7:$E$205,'Aportes tios'!$B$7:$B$205,Configuracion!$B$8,'Aportes tios'!$H$7:$H$205,Configuracion!$B$7) -> 0 | G35: =D10+D35-A35 -> 529320 | I35: =D10-A35 -> 529320
A38: Tio | B38: % cubre | C38: Debe cubrir | D38: Ya envio | E38: Falta por enviar | F38: Saldo a favor | G38: Estado | H38: Nota
A39: Juancho | B39: =Configuracion!$B$22 -> 0.5 | C39: =$A$35*B39 -> 0 | D39: =SUMIFS('Aportes tios'!$E$7:$E$205,'Aportes tios'!$C$7:$C$205,A39,'Aportes tios'!$B$7:$B$205,Configuracion!$B$8,'Aportes tios'!$H$7:$H$205,Configuracion!$B$7) -> 0 | E39: =MAX(0,C39-D39) -> 0 | F39: =MAX(0,D39-C39) -> 0 | G39: =IF(E39>0,"Debe enviar",IF(F39>0,"A favor","OK")) -> OK
A40: Beto | B40: =Configuracion!$B$23 -> 0.5 | C40: =$A$35*B40 -> 0 | D40: =SUMIFS('Aportes tios'!$E$7:$E$205,'Aportes tios'!$C$7:$C$205,A40,'Aportes tios'!$B$7:$B$205,Configuracion!$B$8,'Aportes tios'!$H$7:$H$205,Configuracion!$B$7) -> 0 | E40: =MAX(0,C40-D40) -> 0 | F40: =MAX(0,D40-C40) -> 0 | G40: =IF(E40>0,"Debe enviar",IF(F40>0,"A favor","OK")) -> OK
A41: TOTAL | B41: =SUM(B39:B40) -> 1 | C41: =SUM(C39:C40) -> 0 | D41: =SUM(D39:D40) -> 0 | E41: =SUM(E39:E40) -> 0 | F41: =SUM(F39:F40) -> 0 | G41: =IF(E41>0,"Falta por cubrir",IF(F41>0,"Aportes de mas","OK")) -> OK
A44: GASTOS POR CATEGORIA | B44: GASTOS POR CATEGORIA | C44: GASTOS POR CATEGORIA | D44: GASTOS POR CATEGORIA
A45: Categoria | B45: Total gasto | C45: % del gasto | D45: Nota
A46: =Configuracion!G7 -> ACPM | B46: =SUMIFS('Gastos volqueta'!$E$7:$E$205,'Gastos volqueta'!$C$7:$C$205,A46,'Gastos volqueta'!$B$7:$B$205,Configuracion!$B$8,'Gastos volqueta'!$I$7:$I$205,Configuracion!$B$7) -> 0 | C46: =IF($A$35=0,"",B46/$A$35)
A47: =Configuracion!G8 -> Mantenimiento | B47: =SUMIFS('Gastos volqueta'!$E$7:$E$205,'Gastos volqueta'!$C$7:$C$205,A47,'Gastos volqueta'!$B$7:$B$205,Configuracion!$B$8,'Gastos volqueta'!$I$7:$I$205,Configuracion!$B$7) -> 0 | C47: =IF($A$35=0,"",B47/$A$35)
A48: =Configuracion!G9 -> Llantas | B48: =SUMIFS('Gastos volqueta'!$E$7:$E$205,'Gastos volqueta'!$C$7:$C$205,A48,'Gastos volqueta'!$B$7:$B$205,Configuracion!$B$8,'Gastos volqueta'!$I$7:$I$205,Configuracion!$B$7) -> 0 | C48: =IF($A$35=0,"",B48/$A$35)
A49: =Configuracion!G10 -> Aceite | B49: =SUMIFS('Gastos volqueta'!$E$7:$E$205,'Gastos volqueta'!$C$7:$C$205,A49,'Gastos volqueta'!$B$7:$B$205,Configuracion!$B$8,'Gastos volqueta'!$I$7:$I$205,Configuracion!$B$7) -> 0 | C49: =IF($A$35=0,"",B49/$A$35)
A50: =Configuracion!G11 -> Lavadero | B50: =SUMIFS('Gastos volqueta'!$E$7:$E$205,'Gastos volqueta'!$C$7:$C$205,A50,'Gastos volqueta'!$B$7:$B$205,Configuracion!$B$8,'Gastos volqueta'!$I$7:$I$205,Configuracion!$B$7) -> 0 | C50: =IF($A$35=0,"",B50/$A$35)
A51: =Configuracion!G12 -> Peajes | B51: =SUMIFS('Gastos volqueta'!$E$7:$E$205,'Gastos volqueta'!$C$7:$C$205,A51,'Gastos volqueta'!$B$7:$B$205,Configuracion!$B$8,'Gastos volqueta'!$I$7:$I$205,Configuracion!$B$7) -> 0 | C51: =IF($A$35=0,"",B51/$A$35)
A52: =Configuracion!G13 -> Parqueadero | B52: =SUMIFS('Gastos volqueta'!$E$7:$E$205,'Gastos volqueta'!$C$7:$C$205,A52,'Gastos volqueta'!$B$7:$B$205,Configuracion!$B$8,'Gastos volqueta'!$I$7:$I$205,Configuracion!$B$7) -> 0 | C52: =IF($A$35=0,"",B52/$A$35)
A53: =Configuracion!G14 -> Reparacion | B53: =SUMIFS('Gastos volqueta'!$E$7:$E$205,'Gastos volqueta'!$C$7:$C$205,A53,'Gastos volqueta'!$B$7:$B$205,Configuracion!$B$8,'Gastos volqueta'!$I$7:$I$205,Configuracion!$B$7) -> 0 | C53: =IF($A$35=0,"",B53/$A$35)
...

Sheet Registro diario
A1: REGISTRO DIARIO DE VIAJES | B1: REGISTRO DIARIO DE VIAJES | C1: REGISTRO DIARIO DE VIAJES | D1: REGISTRO DIARIO DE VIAJES | E1: REGISTRO DIARIO DE VIAJES | F1: REGISTRO DIARIO DE VIAJES | G1: REGISTRO DIARIO DE VIAJES | H1: REGISTRO DIARIO DE VIAJES | I1: REGISTRO DIARIO DE VIAJES | J1: REGISTRO DIARIO DE VIAJES | K1: REGISTRO DIARIO DE VIAJES | L1: REGISTRO DIARIO DE VIAJES | M1: REGISTRO DIARIO DE VIAJES | N1: REGISTRO DIARIO DE VIAJES | O1: REGISTRO DIARIO DE VIAJES | P1: REGISTRO DIARIO DE VIAJES
A2: REGISTRO DIARIO DE VIAJES | B2: REGISTRO DIARIO DE VIAJES | C2: REGISTRO DIARIO DE VIAJES | D2: REGISTRO DIARIO DE VIAJES | E2: REGISTRO DIARIO DE VIAJES | F2: REGISTRO DIARIO DE VIAJES | G2: REGISTRO DIARIO DE VIAJES | H2: REGISTRO DIARIO DE VIAJES | I2: REGISTRO DIARIO DE VIAJES | J2: REGISTRO DIARIO DE VIAJES | K2: REGISTRO DIARIO DE VIAJES | L2: REGISTRO DIARIO DE VIAJES | M2: REGISTRO DIARIO DE VIAJES | N2: REGISTRO DIARIO DE VIAJES | O2: REGISTRO DIARIO DE VIAJES | P2: REGISTRO DIARIO DE VIAJES
A3: ="Mes: "&CHOOSE(Configuracion!$B$8,"Enero","Febrero","Marzo","Abril","Mayo","Junio","Julio","Agosto","Septiembre","Octubre","Noviembre","Diciembre")&" "&Configuracion!$B$7&" | Escribe los viajes en las columnas azules." -> Mes: Junio 2026 | Escribe los viajes en las columnas azules.
A5: Meta: 20 viajes de lunes a jueves. Los viajes pendientes se distribuyen automaticamente entre viernes, sabado y domingo. | B5: Meta: 20 viajes de lunes a jueves. Los viajes pendientes se distribuyen automaticamente entre viernes, sabado y domingo. | C5: Meta: 20 viajes de lunes a jueves. Los viajes pendientes se distribuyen automaticamente entre viernes, sabado y domingo. | D5: Meta: 20 viajes de lunes a jueves. Los viajes pendientes se distribuyen automaticamente entre viernes, sabado y domingo. | E5: Meta: 20 viajes de lunes a jueves. Los viajes pendientes se distribuyen automaticamente entre viernes, sabado y domingo. | F5: Meta: 20 viajes de lunes a jueves. Los viajes pendientes se distribuyen automaticamente entre viernes, sabado y domingo. | G5: Meta: 20 viajes de lunes a jueves. Los viajes pendientes se distribuyen automaticamente entre viernes, sabado y domingo. | H5: Meta: 20 viajes de lunes a jueves. Los viajes pendientes se distribuyen automaticamente entre viernes, sabado y domingo. | I5: Meta: 20 viajes de lunes a jueves. Los viajes pendientes se distribuyen automaticamente entre viernes, sabado y domingo. | J5: Meta: 20 viajes de lunes a jueves. Los viajes pendientes se distribuyen automaticamente entre viernes, sabado y domingo. | K5: Meta: 20 viajes de lunes a jueves. Los viajes pendientes se distribuyen automaticamente entre viernes, sabado y domingo. | L5: Meta: 20 viajes de lunes a jueves. Los viajes pendientes se distribuyen automaticamente entre viernes, sabado y domingo. | M5: Meta: 20 viajes de lunes a jueves. Los viajes pendientes se distribuyen automaticamente entre viernes, sabado y domingo. | N5: Meta: 20 viajes de lunes a jueves. Los viajes pendientes se distribuyen automaticamente entre viernes, sabado y domingo. | O5: Meta: 20 viajes de lunes a jueves. Los viajes pendientes se distribuyen automaticamente entre viernes, sabado y domingo. | P5: Meta: 20 viajes de lunes a jueves. Los viajes pendientes se distribuyen automaticamente entre viernes, sabado y domingo.
A6: Fecha | B6: Dia | C6: Semana | D6: Rio a trituradora | E6: Rio a stock | F6: Stock a trituradora | G6: Trituradora a stock | H6: Stock a stock | I6: Total viajes | J6: Meta base L-J | K6: Meta sugerida hoy | L6: Faltan semana | M6: Valor bruto | N6: Mi 22% | O6: Estado | P6: Observaciones
A7: =IF(1<=DAY(EOMONTH(DATE(Configuracion!$B$7,Configuracion!$B$8,1),0)),DATE(Configuracion!$B$7,Configuracion!$B$8,1),"") -> 46174 | B7: =IF(A7="","",CHOOSE(WEEKDAY(A7,2),"Lunes","Martes","Miercoles","Jueves","Viernes","Sabado","Domingo")) -> Lunes | C7: =IF(A7="","",INT((DAY(A7)+WEEKDAY(DATE(YEAR(A7),MONTH(A7),1),2)-2)/7)+1) -> 1 | I7: =IF(A7="","",SUM(D7:H7)) -> 0 | J7: =IF(A7="","",IF(WEEKDAY(A7,2)<=4,Configuracion!$B$9,0)) -> 20 | K7: =IF(A7="","",IF(WEEKDAY(A7,2)<=4,Configuracion!$B$9,IF(SUMIFS($J$7:$J$37,$C$7:$C$37,C7)=0,0,ROUNDUP(MAX(0,SUMIFS($J$7:$J$37,$C$7:$C$37,C7)-SUMIFS($I$7:$I$37,$C$7:$C$37,C7,$A$7:$A$37,"<"&A7))/(8-WEEKDAY(A7,2)),0)))) -> 20 | L7: =IF(A7="","",MAX(0,SUMIFS($J$7:$J$37,$C$7:$C$37,C7)-SUMIFS($I$7:$I$37,$C$7:$C$37,C7,$A$7:$A$37,"<="&A7))) -> 80 | M7: =IF(A7="","",D7*Configuracion!$B$14+E7*Configuracion!$B$15+F7*Configuracion!$B$16+G7*Configuracion!$B$17+H7*Configuracion!$B$18) -> 0 | N7: =IF(A7="","",M7*Configuracion!$B$10) -> 0 | O7: =IF(A7="","",IF(I7=0,"",IF(L7=0,"Meta cumplida",IF(WEEKDAY(A7,2)<=4,"En curso","Recuperando"))))
A8: =IF(2<=DAY(EOMONTH(DATE(Configuracion!$B$7,Configuracion!$B$8,1),0)),DATE(Configuracion!$B$7,Configuracion!$B$8,2),"") -> 46175 | B8: =IF(A8="","",CHOOSE(WEEKDAY(A8,2),"Lunes","Martes","Miercoles","Jueves","Viernes","Sabado","Domingo")) -> Martes | C8: =IF(A8="","",INT((DAY(A8)+WEEKDAY(DATE(YEAR(A8),MONTH(A8),1),2)-2)/7)+1) -> 1 | I8: =IF(A8="","",SUM(D8:H8)) -> 0 | J8: =IF(A8="","",IF(WEEKDAY(A8,2)<=4,Configuracion!$B$9,0)) -> 20 | K8: =IF(A8="","",IF(WEEKDAY(A8,2)<=4,Configuracion!$B$9,IF(SUMIFS($J$7:$J$37,$C$7:$C$37,C8)=0,0,ROUNDUP(MAX(0,SUMIFS($J$7:$J$37,$C$7:$C$37,C8)-SUMIFS($I$7:$I$37,$C$7:$C$37,C8,$A$7:$A$37,"<"&A8))/(8-WEEKDAY(A8,2)),0)))) -> 20 | L8: =IF(A8="","",MAX(0,SUMIFS($J$7:$J$37,$C$7:$C$37,C8)-SUMIFS($I$7:$I$37,$C$7:$C$37,C8,$A$7:$A$37,"<="&A8))) -> 80 | M8: =IF(A8="","",D8*Configuracion!$B$14+E8*Configuracion!$B$15+F8*Configuracion!$B$16+G8*Configuracion!$B$17+H8*Configuracion!$B$18) -> 0 | N8: =IF(A8="","",M8*Configuracion!$B$10) -> 0 | O8: =IF(A8="","",IF(I8=0,"",IF(L8=0,"Meta cumplida",IF(WEEKDAY(A8,2)<=4,"En curso","Recuperando"))))
A9: =IF(3<=DAY(EOMONTH(DATE(Configuracion!$B$7,Configuracion!$B$8,1),0)),DATE(Configuracion!$B$7,Configuracion!$B$8,3),"") -> 46176 | B9: =IF(A9="","",CHOOSE(WEEKDAY(A9,2),"Lunes","Martes","Miercoles","Jueves","Viernes","Sabado","Domingo")) -> Miercoles | C9: =IF(A9="","",INT((DAY(A9)+WEEKDAY(DATE(YEAR(A9),MONTH(A9),1),2)-2)/7)+1) -> 1 | I9: =IF(A9="","",SUM(D9:H9)) -> 0 | J9: =IF(A9="","",IF(WEEKDAY(A9,2)<=4,Configuracion!$B$9,0)) -> 20 | K9: =IF(A9="","",IF(WEEKDAY(A9,2)<=4,Configuracion!$B$9,IF(SUMIFS($J$7:$J$37,$C$7:$C$37,C9)=0,0,ROUNDUP(MAX(0,SUMIFS($J$7:$J$37,$C$7:$C$37,C9)-SUMIFS($I$7:$I$37,$C$7:$C$37,C9,$A$7:$A$37,"<"&A9))/(8-WEEKDAY(A9,2)),0)))) -> 20 | L9: =IF(A9="","",MAX(0,SUMIFS($J$7:$J$37,$C$7:$C$37,C9)-SUMIFS($I$7:$I$37,$C$7:$C$37,C9,$A$7:$A$37,"<="&A9))) -> 80 | M9: =IF(A9="","",D9*Configuracion!$B$14+E9*Configuracion!$B$15+F9*Configuracion!$B$16+G9*Configuracion!$B$17+H9*Configuracion!$B$18) -> 0 | N9: =IF(A9="","",M9*Configuracion!$B$10) -> 0 | O9: =IF(A9="","",IF(I9=0,"",IF(L9=0,"Meta cumplida",IF(WEEKDAY(A9,2)<=4,"En curso","Recuperando"))))
A10: =IF(4<=DAY(EOMONTH(DATE(Configuracion!$B$7,Configuracion!$B$8,1),0)),DATE(Configuracion!$B$7,Configuracion!$B$8,4),"") -> 46177 | B10: =IF(A10="","",CHOOSE(WEEKDAY(A10,2),"Lunes","Martes","Miercoles","Jueves","Viernes","Sabado","Domingo")) -> Jueves | C10: =IF(A10="","",INT((DAY(A10)+WEEKDAY(DATE(YEAR(A10),MONTH(A10),1),2)-2)/7)+1) -> 1 | I10: =IF(A10="","",SUM(D10:H10)) -> 0 | J10: =IF(A10="","",IF(WEEKDAY(A10,2)<=4,Configuracion!$B$9,0)) -> 20 | K10: =IF(A10="","",IF(WEEKDAY(A10,2)<=4,Configuracion!$B$9,IF(SUMIFS($J$7:$J$37,$C$7:$C$37,C10)=0,0,ROUNDUP(MAX(0,SUMIFS($J$7:$J$37,$C$7:$C$37,C10)-SUMIFS($I$7:$I$37,$C$7:$C$37,C10,$A$7:$A$37,"<"&A10))/(8-WEEKDAY(A10,2)),0)))) -> 20 | L10: =IF(A10="","",MAX(0,SUMIFS($J$7:$J$37,$C$7:$C$37,C10)-SUMIFS($I$7:$I$37,$C$7:$C$37,C10,$A$7:$A$37,"<="&A10))) -> 80 | M10: =IF(A10="","",D10*Configuracion!$B$14+E10*Configuracion!$B$15+F10*Configuracion!$B$16+G10*Configuracion!$B$17+H10*Configuracion!$B$18) -> 0 | N10: =IF(A10="","",M10*Configuracion!$B$10) -> 0 | O10: =IF(A10="","",IF(I10=0,"",IF(L10=0,"Meta cumplida",IF(WEEKDAY(A10,2)<=4,"En curso","Recuperando"))))
A11: =IF(5<=DAY(EOMONTH(DATE(Configuracion!$B$7,Configuracion!$B$8,1),0)),DATE(Configuracion!$B$7,Configuracion!$B$8,5),"") -> 46178 | B11: =IF(A11="","",CHOOSE(WEEKDAY(A11,2),"Lunes","Martes","Miercoles","Jueves","Viernes","Sabado","Domingo")) -> Viernes | C11: =IF(A11="","",INT((DAY(A11)+WEEKDAY(DATE(YEAR(A11),MONTH(A11),1),2)-2)/7)+1) -> 1 | I11: =IF(A11="","",SUM(D11:H11)) -> 0 | J11: =IF(A11="","",IF(WEEKDAY(A11,2)<=4,Configuracion!$B$9,0)) -> 0 | K11: =IF(A11="","",IF(WEEKDAY(A11,2)<=4,Configuracion!$B$9,IF(SUMIFS($J$7:$J$37,$C$7:$C$37,C11)=0,0,ROUNDUP(MAX(0,SUMIFS($J$7:$J$37,$C$7:$C$37,C11)-SUMIFS($I$7:$I$37,$C$7:$C$37,C11,$A$7:$A$37,"<"&A11))/(8-WEEKDAY(A11,2)),0)))) -> 27 | L11: =IF(A11="","",MAX(0,SUMIFS($J$7:$J$37,$C$7:$C$37,C11)-SUMIFS($I$7:$I$37,$C$7:$C$37,C11,$A$7:$A$37,"<="&A11))) -> 80 | M11: =IF(A11="","",D11*Configuracion!$B$14+E11*Configuracion!$B$15+F11*Configuracion!$B$16+G11*Configuracion!$B$17+H11*Configuracion!$B$18) -> 0 | N11: =IF(A11="","",M11*Configuracion!$B$10) -> 0 | O11: =IF(A11="","",IF(I11=0,"",IF(L11=0,"Meta cumplida",IF(WEEKDAY(A11,2)<=4,"En curso","Recuperando"))))
A12: =IF(6<=DAY(EOMONTH(DATE(Configuracion!$B$7,Configuracion!$B$8,1),0)),DATE(Configuracion!$B$7,Configuracion!$B$8,6),"") -> 46179 | B12: =IF(A12="","",CHOOSE(WEEKDAY(A12,2),"Lunes","Martes","Miercoles","Jueves","Viernes","Sabado","Domingo")) -> Sabado | C12: =IF(A12="","",INT((DAY(A12)+WEEKDAY(DATE(YEAR(A12),MONTH(A12),1),2)-2)/7)+1) -> 1 | I12: =IF(A12="","",SUM(D12:H12)) -> 0 | J12: =IF(A12="","",IF(WEEKDAY(A12,2)<=4,Configuracion!$B$9,0)) -> 0 | K12: =IF(A12="","",IF(WEEKDAY(A12,2)<=4,Configuracion!$B$9,IF(SUMIFS($J$7:$J$37,$C$7:$C$37,C12)=0,0,ROUNDUP(MAX(0,SUMIFS($J$7:$J$37,$C$7:$C$37,C12)-SUMIFS($I$7:$I$37,$C$7:$C$37,C12,$A$7:$A$37,"<"&A12))/(8-WEEKDAY(A12,2)),0)))) -> 40 | L12: =IF(A12="","",MAX(0,SUMIFS($J$7:$J$37,$C$7:$C$37,C12)-SUMIFS($I$7:$I$37,$C$7:$C$37,C12,$A$7:$A$37,"<="&A12))) -> 80 | M12: =IF(A12="","",D12*Configuracion!$B$14+E12*Configuracion!$B$15+F12*Configuracion!$B$16+G12*Configuracion!$B$17+H12*Configuracion!$B$18) -> 0 | N12: =IF(A12="","",M12*Configuracion!$B$10) -> 0 | O12: =IF(A12="","",IF(I12=0,"",IF(L12=0,"Meta cumplida",IF(WEEKDAY(A12,2)<=4,"En curso","Recuperando"))))
A13: =IF(7<=DAY(EOMONTH(DATE(Configuracion!$B$7,Configuracion!$B$8,1),0)),DATE(Configuracion!$B$7,Configuracion!$B$8,7),"") -> 46180 | B13: =IF(A13="","",CHOOSE(WEEKDAY(A13,2),"Lunes","Martes","Miercoles","Jueves","Viernes","Sabado","Domingo")) -> Domingo | C13: =IF(A13="","",INT((DAY(A13)+WEEKDAY(DATE(YEAR(A13),MONTH(A13),1),2)-2)/7)+1) -> 1 | I13: =IF(A13="","",SUM(D13:H13)) -> 0 | J13: =IF(A13="","",IF(WEEKDAY(A13,2)<=4,Configuracion!$B$9,0)) -> 0 | K13: =IF(A13="","",IF(WEEKDAY(A13,2)<=4,Configuracion!$B$9,IF(SUMIFS($J$7:$J$37,$C$7:$C$37,C13)=0,0,ROUNDUP(MAX(0,SUMIFS($J$7:$J$37,$C$7:$C$37,C13)-SUMIFS($I$7:$I$37,$C$7:$C$37,C13,$A$7:$A$37,"<"&A13))/(8-WEEKDAY(A13,2)),0)))) -> 80 | L13: =IF(A13="","",MAX(0,SUMIFS($J$7:$J$37,$C$7:$C$37,C13)-SUMIFS($I$7:$I$37,$C$7:$C$37,C13,$A$7:$A$37,"<="&A13))) -> 80 | M13: =IF(A13="","",D13*Configuracion!$B$14+E13*Configuracion!$B$15+F13*Configuracion!$B$16+G13*Configuracion!$B$17+H13*Configuracion!$B$18) -> 0 | N13: =IF(A13="","",M13*Configuracion!$B$10) -> 0 | O13: =IF(A13="","",IF(I13=0,"",IF(L13=0,"Meta cumplida",IF(WEEKDAY(A13,2)<=4,"En curso","Recuperando"))))
A14: =IF(8<=DAY(EOMONTH(DATE(Configuracion!$B$7,Configuracion!$B$8,1),0)),DATE(Configuracion!$B$7,Configuracion!$B$8,8),"") -> 46181 | B14: =IF(A14="","",CHOOSE(WEEKDAY(A14,2),"Lunes","Martes","Miercoles","Jueves","Viernes","Sabado","Domingo")) -> Lunes | C14: =IF(A14="","",INT((DAY(A14)+WEEKDAY(DATE(YEAR(A14),MONTH(A14),1),2)-2)/7)+1) -> 2 | I14: =IF(A14="","",SUM(D14:H14)) -> 0 | J14: =IF(A14="","",IF(WEEKDAY(A14,2)<=4,Configuracion!$B$9,0)) -> 20 | K14: =IF(A14="","",IF(WEEKDAY(A14,2)<=4,Configuracion!$B$9,IF(SUMIFS($J$7:$J$37,$C$7:$C$37,C14)=0,0,ROUNDUP(MAX(0,SUMIFS($J$7:$J$37,$C$7:$C$37,C14)-SUMIFS($I$7:$I$37,$C$7:$C$37,C14,$A$7:$A$37,"<"&A14))/(8-WEEKDAY(A14,2)),0)))) -> 20 | L14: =IF(A14="","",MAX(0,SUMIFS($J$7:$J$37,$C$7:$C$37,C14)-SUMIFS($I$7:$I$37,$C$7:$C$37,C14,$A$7:$A$37,"<="&A14))) -> 80 | M14: =IF(A14="","",D14*Configuracion!$B$14+E14*Configuracion!$B$15+F14*Configuracion!$B$16+G14*Configuracion!$B$17+H14*Configuracion!$B$18) -> 0 | N14: =IF(A14="","",M14*Configuracion!$B$10) -> 0 | O14: =IF(A14="","",IF(I14=0,"",IF(L14=0,"Meta cumplida",IF(WEEKDAY(A14,2)<=4,"En curso","Recuperando"))))
A15: =IF(9<=DAY(EOMONTH(DATE(Configuracion!$B$7,Configuracion!$B$8,1),0)),DATE(Configuracion!$B$7,Configuracion!$B$8,9),"") -> 46182 | B15: =IF(A15="","",CHOOSE(WEEKDAY(A15,2),"Lunes","Martes","Miercoles","Jueves","Viernes","Sabado","Domingo")) -> Martes | C15: =IF(A15="","",INT((DAY(A15)+WEEKDAY(DATE(YEAR(A15),MONTH(A15),1),2)-2)/7)+1) -> 2 | I15: =IF(A15="","",SUM(D15:H15)) -> 0 | J15: =IF(A15="","",IF(WEEKDAY(A15,2)<=4,Configuracion!$B$9,0)) -> 20 | K15: =IF(A15="","",IF(WEEKDAY(A15,2)<=4,Configuracion!$B$9,IF(SUMIFS($J$7:$J$37,$C$7:$C$37,C15)=0,0,ROUNDUP(MAX(0,SUMIFS($J$7:$J$37,$C$7:$C$37,C15)-SUMIFS($I$7:$I$37,$C$7:$C$37,C15,$A$7:$A$37,"<"&A15))/(8-WEEKDAY(A15,2)),0)))) -> 20 | L15: =IF(A15="","",MAX(0,SUMIFS($J$7:$J$37,$C$7:$C$37,C15)-SUMIFS($I$7:$I$37,$C$7:$C$37,C15,$A$7:$A$37,"<="&A15))) -> 80 | M15: =IF(A15="","",D15*Configuracion!$B$14+E15*Configuracion!$B$15+F15*Configuracion!$B$16+G15*Configuracion!$B$17+H15*Configuracion!$B$18) -> 0 | N15: =IF(A15="","",M15*Configuracion!$B$10) -> 0 | O15: =IF(A15="","",IF(I15=0,"",IF(L15=0,"Meta cumplida",IF(WEEKDAY(A15,2)<=4,"En curso","Recuperando"))))
A16: =IF(10<=DAY(EOMONTH(DATE(Configuracion!$B$7,Configuracion!$B$8,1),0)),DATE(Configuracion!$B$7,Configuracion!$B$8,10),"") -> 46183 | B16: =IF(A16="","",CHOOSE(WEEKDAY(A16,2),"Lunes","Martes","Miercoles","Jueves","Viernes","Sabado","Domingo")) -> Miercoles | C16: =IF(A16="","",INT((DAY(A16)+WEEKDAY(DATE(YEAR(A16),MONTH(A16),1),2)-2)/7)+1) -> 2 | F16: 1 | H16: 1 | I16: =IF(A16="","",SUM(D16:H16)) -> 2 | J16: =IF(A16="","",IF(WEEKDAY(A16,2)<=4,Configuracion!$B$9,0)) -> 20 | K16: =IF(A16="","",IF(WEEKDAY(A16,2)<=4,Configuracion!$B$9,IF(SUMIFS($J$7:$J$37,$C$7:$C$37,C16)=0,0,ROUNDUP(MAX(0,SUMIFS($J$7:$J$37,$C$7:$C$37,C16)-SUMIFS($I$7:$I$37,$C$7:$C$37,C16,$A$7:$A$37,"<"&A16))/(8-WEEKDAY(A16,2)),0)))) -> 20 | L16: =IF(A16="","",MAX(0,SUMIFS($J$7:$J$37,$C$7:$C$37,C16)-SUMIFS($I$7:$I$37,$C$7:$C$37,C16,$A$7:$A$37,"<="&A16))) -> 78 | M16: =IF(A16="","",D16*Configuracion!$B$14+E16*Configuracion!$B$15+F16*Configuracion!$B$16+G16*Configuracion!$B$17+H16*Configuracion!$B$18) -> 28000 | N16: =IF(A16="","",M16*Configuracion!$B$10) -> 6160 | O16: =IF(A16="","",IF(I16=0,"",IF(L16=0,"Meta cumplida",IF(WEEKDAY(A16,2)<=4,"En curso","Recuperando")))) -> En curso
A17: =IF(11<=DAY(EOMONTH(DATE(Configuracion!$B$7,Configuracion!$B$8,1),0)),DATE(Configuracion!$B$7,Configuracion!$B$8,11),"") -> 46184 | B17: =IF(A17="","",CHOOSE(WEEKDAY(A17,2),"Lunes","Martes","Miercoles","Jueves","Viernes","Sabado","Domingo")) -> Jueves | C17: =IF(A17="","",INT((DAY(A17)+WEEKDAY(DATE(YEAR(A17),MONTH(A17),1),2)-2)/7)+1) -> 2 | D17: 16 | E17: 1 | I17: =IF(A17="","",SUM(D17:H17)) -> 17 | J17: =IF(A17="","",IF(WEEKDAY(A17,2)<=4,Configuracion!$B$9,0)) -> 20 | K17: =IF(A17="","",IF(WEEKDAY(A17,2)<=4,Configuracion!$B$9,IF(SUMIFS($J$7:$J$37,$C$7:$C$37,C17)=0,0,ROUNDUP(MAX(0,SUMIFS($J$7:$J$37,$C$7:$C$37,C17)-SUMIFS($I$7:$I$37,$C$7:$C$37,C17,$A$7:$A$37,"<"&A17))/(8-WEEKDAY(A17,2)),0)))) -> 20 | L17: =IF(A17="","",MAX(0,SUMIFS($J$7:$J$37,$C$7:$C$37,C17)-SUMIFS($I$7:$I$37,$C$7:$C$37,C17,$A$7:$A$37,"<="&A17))) -> 61 | M17: =IF(A17="","",D17*Configuracion!$B$14+E17*Configuracion!$B$15+F17*Configuracion!$B$16+G17*Configuracion!$B$17+H17*Configuracion!$B$18) -> 542000 | N17: =IF(A17="","",M17*Configuracion!$B$10) -> 119240 | O17: =IF(A17="","",IF(I17=0,"",IF(L17=0,"Meta cumplida",IF(WEEKDAY(A17,2)<=4,"En curso","Recuperando")))) -> En curso
A18: =IF(12<=DAY(EOMONTH(DATE(Configuracion!$B$7,Configuracion!$B$8,1),0)),DATE(Configuracion!$B$7,Configuracion!$B$8,12),"") -> 46185 | B18: =IF(A18="","",CHOOSE(WEEKDAY(A18,2),"Lunes","Martes","Miercoles","Jueves","Viernes","Sabado","Domingo")) -> Viernes | C18: =IF(A18="","",INT((DAY(A18)+WEEKDAY(DATE(YEAR(A18),MONTH(A18),1),2)-2)/7)+1) -> 2 | D18: 10 | I18: =IF(A18="","",SUM(D18:H18)) -> 10 | J18: =IF(A18="","",IF(WEEKDAY(A18,2)<=4,Configuracion!$B$9,0)) -> 0 | K18: =IF(A18="","",IF(WEEKDAY(A18,2)<=4,Configuracion!$B$9,IF(SUMIFS($J$7:$J$37,$C$7:$C$37,C18)=0,0,ROUNDUP(MAX(0,SUMIFS($J$7:$J$37,$C$7:$C$37,C18)-SUMIFS($I$7:$I$37,$C$7:$C$37,C18,$A$7:$A$37,"<"&A18))/(8-WEEKDAY(A18,2)),0)))) -> 21 | L18: =IF(A18="","",MAX(0,SUMIFS($J$7:$J$37,$C$7:$C$37,C18)-SUMIFS($I$7:$I$37,$C$7:$C$37,C18,$A$7:$A$37,"<="&A18))) -> 51 | M18: =IF(A18="","",D18*Configuracion!$B$14+E18*Configuracion!$B$15+F18*Configuracion!$B$16+G18*Configuracion!$B$17+H18*Configuracion!$B$18) -> 320000 | N18: =IF(A18="","",M18*Configuracion!$B$10) -> 70400 | O18: =IF(A18="","",IF(I18=0,"",IF(L18=0,"Meta cumplida",IF(WEEKDAY(A18,2)<=4,"En curso","Recuperando")))) -> Recuperando
A19: =IF(13<=DAY(EOMONTH(DATE(Configuracion!$B$7,Configuracion!$B$8,1),0)),DATE(Configuracion!$B$7,Configuracion!$B$8,13),"") -> 46186 | B19: =IF(A19="","",CHOOSE(WEEKDAY(A19,2),"Lunes","Martes","Miercoles","Jueves","Viernes","Sabado","Domingo")) -> Sabado | C19: =IF(A19="","",INT((DAY(A19)+WEEKDAY(DATE(YEAR(A19),MONTH(A19),1),2)-2)/7)+1) -> 2 | D19: 19 | E19: 1 | I19: =IF(A19="","",SUM(D19:H19)) -> 20 | J19: =IF(A19="","",IF(WEEKDAY(A19,2)<=4,Configuracion!$B$9,0)) -> 0 | K19: =IF(A19="","",IF(WEEKDAY(A19,2)<=4,Configuracion!$B$9,IF(SUMIFS($J$7:$J$37,$C$7:$C$37,C19)=0,0,ROUNDUP(MAX(0,SUMIFS($J$7:$J$37,$C$7:$C$37,C19)-SUMIFS($I$7:$I$37,$C$7:$C$37,C19,$A$7:$A$37,"<"&A19))/(8-WEEKDAY(A19,2)),0)))) -> 26 | L19: =IF(A19="","",MAX(0,SUMIFS($J$7:$J$37,$C$7:$C$37,C19)-SUMIFS($I$7:$I$37,$C$7:$C$37,C19,$A$7:$A$37,"<="&A19))) -> 31 | M19: =IF(A19="","",D19*Configuracion!$B$14+E19*Configuracion!$B$15+F19*Configuracion!$B$16+G19*Configuracion!$B$17+H19*Configuracion!$B$18) -> 638000 | N19: =IF(A19="","",M19*Configuracion!$B$10) -> 140360 | O19: =IF(A19="","",IF(I19=0,"",IF(L19=0,"Meta cumplida",IF(WEEKDAY(A19,2)<=4,"En curso","Recuperando")))) -> Recuperando
A20: =IF(14<=DAY(EOMONTH(DATE(Configuracion!$B$7,Configuracion!$B$8,1),0)),DATE(Configuracion!$B$7,Configuracion!$B$8,14),"") -> 46187 | B20: =IF(A20="","",CHOOSE(WEEKDAY(A20,2),"Lunes","Martes","Miercoles","Jueves","Viernes","Sabado","Domingo")) -> Domingo | C20: =IF(A20="","",INT((DAY(A20)+WEEKDAY(DATE(YEAR(A20),MONTH(A20),1),2)-2)/7)+1) -> 2 | D20: 19 | E20: 1 | I20: =IF(A20="","",SUM(D20:H20)) -> 20 | J20: =IF(A20="","",IF(WEEKDAY(A20,2)<=4,Configuracion!$B$9,0)) -> 0 | K20: =IF(A20="","",IF(WEEKDAY(A20,2)<=4,Configuracion!$B$9,IF(SUMIFS($J$7:$J$37,$C$7:$C$37,C20)=0,0,ROUNDUP(MAX(0,SUMIFS($J$7:$J$37,$C$7:$C$37,C20)-SUMIFS($I$7:$I$37,$C$7:$C$37,C20,$A$7:$A$37,"<"&A20))/(8-WEEKDAY(A20,2)),0)))) -> 31 | L20: =IF(A20="","",MAX(0,SUMIFS($J$7:$J$37,$C$7:$C$37,C20)-SUMIFS($I$7:$I$37,$C$7:$C$37,C20,$A$7:$A$37,"<="&A20))) -> 11 | M20: =IF(A20="","",D20*Configuracion!$B$14+E20*Configuracion!$B$15+F20*Configuracion!$B$16+G20*Configuracion!$B$17+H20*Configuracion!$B$18) -> 638000 | N20: =IF(A20="","",M20*Configuracion!$B$10) -> 140360 | O20: =IF(A20="","",IF(I20=0,"",IF(L20=0,"Meta cumplida",IF(WEEKDAY(A20,2)<=4,"En curso","Recuperando")))) -> Recuperando
A21: =IF(15<=DAY(EOMONTH(DATE(Configuracion!$B$7,Configuracion!$B$8,1),0)),DATE(Configuracion!$B$7,Configuracion!$B$8,15),"") -> 46188 | B21: =IF(A21="","",CHOOSE(WEEKDAY(A21,2),"Lunes","Martes","Miercoles","Jueves","Viernes","Sabado","Domingo")) -> Lunes | C21: =IF(A21="","",INT((DAY(A21)+WEEKDAY(DATE(YEAR(A21),MONTH(A21),1),2)-2)/7)+1) -> 3 | D21: 3 | F21: 9 | I21: =IF(A21="","",SUM(D21:H21)) -> 12 | J21: =IF(A21="","",IF(WEEKDAY(A21,2)<=4,Configuracion!$B$9,0)) -> 20 | K21: =IF(A21="","",IF(WEEKDAY(A21,2)<=4,Configuracion!$B$9,IF(SUMIFS($J$7:$J$37,$C$7:$C$37,C21)=0,0,ROUNDUP(MAX(0,SUMIFS($J$7:$J$37,$C$7:$C$37,C21)-SUMIFS($I$7:$I$37,$C$7:$C$37,C21,$A$7:$A$37,"<"&A21))/(8-WEEKDAY(A21,2)),0)))) -> 20 | L21: =IF(A21="","",MAX(0,SUMIFS($J$7:$J$37,$C$7:$C$37,C21)-SUMIFS($I$7:$I$37,$C$7:$C$37,C21,$A$7:$A$37,"<="&A21))) -> 68 | M21: =IF(A21="","",D21*Configuracion!$B$14+E21*Configuracion!$B$15+F21*Configuracion!$B$16+G21*Configuracion!$B$17+H21*Configuracion!$B$18) -> 240000 | N21: =IF(A21="","",M21*Configuracion!$B$10) -> 52800 | O21: =IF(A21="","",IF(I21=0,"",IF(L21=0,"Meta cumplida",IF(WEEKDAY(A21,2)<=4,"En curso","Recuperando")))) -> En curso
A22: =IF(16<=DAY(EOMONTH(DATE(Configuracion!$B$7,Configuracion!$B$8,1),0)),DATE(Configuracion!$B$7,Configuracion!$B$8,16),"") -> 46189 | B22: =IF(A22="","",CHOOSE(WEEKDAY(A22,2),"Lunes","Martes","Miercoles","Jueves","Viernes","Sabado","Domingo")) -> Martes | C22: =IF(A22="","",INT((DAY(A22)+WEEKDAY(DATE(YEAR(A22),MONTH(A22),1),2)-2)/7)+1) -> 3 | I22: =IF(A22="","",SUM(D22:H22)) -> 0 | J22: =IF(A22="","",IF(WEEKDAY(A22,2)<=4,Configuracion!$B$9,0)) -> 20 | K22: =IF(A22="","",IF(WEEKDAY(A22,2)<=4,Configuracion!$B$9,IF(SUMIFS($J$7:$J$37,$C$7:$C$37,C22)=0,0,ROUNDUP(MAX(0,SUMIFS($J$7:$J$37,$C$7:$C$37,C22)-SUMIFS($I$7:$I$37,$C$7:$C$37,C22,$A$7:$A$37,"<"&A22))/(8-WEEKDAY(A22,2)),0)))) -> 20 | L22: =IF(A22="","",MAX(0,SUMIFS($J$7:$J$37,$C$7:$C$37,C22)-SUMIFS($I$7:$I$37,$C$7:$C$37,C22,$A$7:$A$37,"<="&A22))) -> 68 | M22: =IF(A22="","",D22*Configuracion!$B$14+E22*Configuracion!$B$15+F22*Configuracion!$B$16+G22*Configuracion!$B$17+H22*Configuracion!$B$18) -> 0 | N22: =IF(A22="","",M22*Configuracion!$B$10) -> 0 | O22: =IF(A22="","",IF(I22=0,"",IF(L22=0,"Meta cumplida",IF(WEEKDAY(A22,2)<=4,"En curso","Recuperando"))))
A23: =IF(17<=DAY(EOMONTH(DATE(Configuracion!$B$7,Configuracion!$B$8,1),0)),DATE(Configuracion!$B$7,Configuracion!$B$8,17),"") -> 46190 | B23: =IF(A23="","",CHOOSE(WEEKDAY(A23,2),"Lunes","Martes","Miercoles","Jueves","Viernes","Sabado","Domingo")) -> Miercoles | C23: =IF(A23="","",INT((DAY(A23)+WEEKDAY(DATE(YEAR(A23),MONTH(A23),1),2)-2)/7)+1) -> 3 | I23: =IF(A23="","",SUM(D23:H23)) -> 0 | J23: =IF(A23="","",IF(WEEKDAY(A23,2)<=4,Configuracion!$B$9,0)) -> 20 | K23: =IF(A23="","",IF(WEEKDAY(A23,2)<=4,Configuracion!$B$9,IF(SUMIFS($J$7:$J$37,$C$7:$C$37,C23)=0,0,ROUNDUP(MAX(0,SUMIFS($J$7:$J$37,$C$7:$C$37,C23)-SUMIFS($I$7:$I$37,$C$7:$C$37,C23,$A$7:$A$37,"<"&A23))/(8-WEEKDAY(A23,2)),0)))) -> 20 | L23: =IF(A23="","",MAX(0,SUMIFS($J$7:$J$37,$C$7:$C$37,C23)-SUMIFS($I$7:$I$37,$C$7:$C$37,C23,$A$7:$A$37,"<="&A23))) -> 68 | M23: =IF(A23="","",D23*Configuracion!$B$14+E23*Configuracion!$B$15+F23*Configuracion!$B$16+G23*Configuracion!$B$17+H23*Configuracion!$B$18) -> 0 | N23: =IF(A23="","",M23*Configuracion!$B$10) -> 0 | O23: =IF(A23="","",IF(I23=0,"",IF(L23=0,"Meta cumplida",IF(WEEKDAY(A23,2)<=4,"En curso","Recuperando"))))
A24: =IF(18<=DAY(EOMONTH(DATE(Configuracion!$B$7,Configuracion!$B$8,1),0)),DATE(Configuracion!$B$7,Configuracion!$B$8,18),"") -> 46191 | B24: =IF(A24="","",CHOOSE(WEEKDAY(A24,2),"Lunes","Martes","Miercoles","Jueves","Viernes","Sabado","Domingo")) -> Jueves | C24: =IF(A24="","",INT((DAY(A24)+WEEKDAY(DATE(YEAR(A24),MONTH(A24),1),2)-2)/7)+1) -> 3 | I24: =IF(A24="","",SUM(D24:H24)) -> 0 | J24: =IF(A24="","",IF(WEEKDAY(A24,2)<=4,Configuracion!$B$9,0)) -> 20 | K24: =IF(A24="","",IF(WEEKDAY(A24,2)<=4,Configuracion!$B$9,IF(SUMIFS($J$7:$J$37,$C$7:$C$37,C24)=0,0,ROUNDUP(MAX(0,SUMIFS($J$7:$J$37,$C$7:$C$37,C24)-SUMIFS($I$7:$I$37,$C$7:$C$37,C24,$A$7:$A$37,"<"&A24))/(8-WEEKDAY(A24,2)),0)))) -> 20 | L24: =IF(A24="","",MAX(0,SUMIFS($J$7:$J$37,$C$7:$C$37,C24)-SUMIFS($I$7:$I$37,$C$7:$C$37,C24,$A$7:$A$37,"<="&A24))) -> 68 | M24: =IF(A24="","",D24*Configuracion!$B$14+E24*Configuracion!$B$15+F24*Configuracion!$B$16+G24*Configuracion!$B$17+H24*Configuracion!$B$18) -> 0 | N24: =IF(A24="","",M24*Configuracion!$B$10) -> 0 | O24: =IF(A24="","",IF(I24=0,"",IF(L24=0,"Meta cumplida",IF(WEEKDAY(A24,2)<=4,"En curso","Recuperando"))))
A25: =IF(19<=DAY(EOMONTH(DATE(Configuracion!$B$7,Configuracion!$B$8,1),0)),DATE(Configuracion!$B$7,Configuracion!$B$8,19),"") -> 46192 | B25: =IF(A25="","",CHOOSE(WEEKDAY(A25,2),"Lunes","Martes","Miercoles","Jueves","Viernes","Sabado","Domingo")) -> Viernes | C25: =IF(A25="","",INT((DAY(A25)+WEEKDAY(DATE(YEAR(A25),MONTH(A25),1),2)-2)/7)+1) -> 3 | I25: =IF(A25="","",SUM(D25:H25)) -> 0 | J25: =IF(A25="","",IF(WEEKDAY(A25,2)<=4,Configuracion!$B$9,0)) -> 0 | K25: =IF(A25="","",IF(WEEKDAY(A25,2)<=4,Configuracion!$B$9,IF(SUMIFS($J$7:$J$37,$C$7:$C$37,C25)=0,0,ROUNDUP(MAX(0,SUMIFS($J$7:$J$37,$C$7:$C$37,C25)-SUMIFS($I$7:$I$37,$C$7:$C$37,C25,$A$7:$A$37,"<"&A25))/(8-WEEKDAY(A25,2)),0)))) -> 23 | L25: =IF(A25="","",MAX(0,SUMIFS($J$7:$J$37,$C$7:$C$37,C25)-SUMIFS($I$7:$I$37,$C$7:$C$37,C25,$A$7:$A$37,"<="&A25))) -> 68 | M25: =IF(A25="","",D25*Configuracion!$B$14+E25*Configuracion!$B$15+F25*Configuracion!$B$16+G25*Configuracion!$B$17+H25*Configuracion!$B$18) -> 0 | N25: =IF(A25="","",M25*Configuracion!$B$10) -> 0 | O25: =IF(A25="","",IF(I25=0,"",IF(L25=0,"Meta cumplida",IF(WEEKDAY(A25,2)<=4,"En curso","Recuperando"))))
A26: =IF(20<=DAY(EOMONTH(DATE(Configuracion!$B$7,Configuracion!$B$8,1),0)),DATE(Configuracion!$B$7,Configuracion!$B$8,20),"") -> 46193 | B26: =IF(A26="","",CHOOSE(WEEKDAY(A26,2),"Lunes","Martes","Miercoles","Jueves","Viernes","Sabado","Domingo")) -> Sabado | C26: =IF(A26="","",INT((DAY(A26)+WEEKDAY(DATE(YEAR(A26),MONTH(A26),1),2)-2)/7)+1) -> 3 | I26: =IF(A26="","",SUM(D26:H26)) -> 0 | J26: =IF(A26="","",IF(WEEKDAY(A26,2)<=4,Configuracion!$B$9,0)) -> 0 | K26: =IF(A26="","",IF(WEEKDAY(A26,2)<=4,Configuracion!$B$9,IF(SUMIFS($J$7:$J$37,$C$7:$C$37,C26)=0,0,ROUNDUP(MAX(0,SUMIFS($J$7:$J$37,$C$7:$C$37,C26)-SUMIFS($I$7:$I$37,$C$7:$C$37,C26,$A$7:$A$37,"<"&A26))/(8-WEEKDAY(A26,2)),0)))) -> 34 | L26: =IF(A26="","",MAX(0,SUMIFS($J$7:$J$37,$C$7:$C$37,C26)-SUMIFS($I$7:$I$37,$C$7:$C$37,C26,$A$7:$A$37,"<="&A26))) -> 68 | M26: =IF(A26="","",D26*Configuracion!$B$14+E26*Configuracion!$B$15+F26*Configuracion!$B$16+G26*Configuracion!$B$17+H26*Configuracion!$B$18) -> 0 | N26: =IF(A26="","",M26*Configuracion!$B$10) -> 0 | O26: =IF(A26="","",IF(I26=0,"",IF(L26=0,"Meta cumplida",IF(WEEKDAY(A26,2)<=4,"En curso","Recuperando"))))
A27: =IF(21<=DAY(EOMONTH(DATE(Configuracion!$B$7,Configuracion!$B$8,1),0)),DATE(Configuracion!$B$7,Configuracion!$B$8,21),"") -> 46194 | B27: =IF(A27="","",CHOOSE(WEEKDAY(A27,2),"Lunes","Martes","Miercoles","Jueves","Viernes","Sabado","Domingo")) -> Domingo | C27: =IF(A27="","",INT((DAY(A27)+WEEKDAY(DATE(YEAR(A27),MONTH(A27),1),2)-2)/7)+1) -> 3 | I27: =IF(A27="","",SUM(D27:H27)) -> 0 | J27: =IF(A27="","",IF(WEEKDAY(A27,2)<=4,Configuracion!$B$9,0)) -> 0 | K27: =IF(A27="","",IF(WEEKDAY(A27,2)<=4,Configuracion!$B$9,IF(SUMIFS($J$7:$J$37,$C$7:$C$37,C27)=0,0,ROUNDUP(MAX(0,SUMIFS($J$7:$J$37,$C$7:$C$37,C27)-SUMIFS($I$7:$I$37,$C$7:$C$37,C27,$A$7:$A$37,"<"&A27))/(8-WEEKDAY(A27,2)),0)))) -> 68 | L27: =IF(A27="","",MAX(0,SUMIFS($J$7:$J$37,$C$7:$C$37,C27)-SUMIFS($I$7:$I$37,$C$7:$C$37,C27,$A$7:$A$37,"<="&A27))) -> 68 | M27: =IF(A27="","",D27*Configuracion!$B$14+E27*Configuracion!$B$15+F27*Configuracion!$B$16+G27*Configuracion!$B$17+H27*Configuracion!$B$18) -> 0 | N27: =IF(A27="","",M27*Configuracion!$B$10) -> 0 | O27: =IF(A27="","",IF(I27=0,"",IF(L27=0,"Meta cumplida",IF(WEEKDAY(A27,2)<=4,"En curso","Recuperando"))))
A28: =IF(22<=DAY(EOMONTH(DATE(Configuracion!$B$7,Configuracion!$B$8,1),0)),DATE(Configuracion!$B$7,Configuracion!$B$8,22),"") -> 46195 | B28: =IF(A28="","",CHOOSE(WEEKDAY(A28,2),"Lunes","Martes","Miercoles","Jueves","Viernes","Sabado","Domingo")) -> Lunes | C28: =IF(A28="","",INT((DAY(A28)+WEEKDAY(DATE(YEAR(A28),MONTH(A28),1),2)-2)/7)+1) -> 4 | I28: =IF(A28="","",SUM(D28:H28)) -> 0 | J28: =IF(A28="","",IF(WEEKDAY(A28,2)<=4,Configuracion!$B$9,0)) -> 20 | K28: =IF(A28="","",IF(WEEKDAY(A28,2)<=4,Configuracion!$B$9,IF(SUMIFS($J$7:$J$37,$C$7:$C$37,C28)=0,0,ROUNDUP(MAX(0,SUMIFS($J$7:$J$37,$C$7:$C$37,C28)-SUMIFS($I$7:$I$37,$C$7:$C$37,C28,$A$7:$A$37,"<"&A28))/(8-WEEKDAY(A28,2)),0)))) -> 20 | L28: =IF(A28="","",MAX(0,SUMIFS($J$7:$J$37,$C$7:$C$37,C28)-SUMIFS($I$7:$I$37,$C$7:$C$37,C28,$A$7:$A$37,"<="&A28))) -> 80 | M28: =IF(A28="","",D28*Configuracion!$B$14+E28*Configuracion!$B$15+F28*Configuracion!$B$16+G28*Configuracion!$B$17+H28*Configuracion!$B$18) -> 0 | N28: =IF(A28="","",M28*Configuracion!$B$10) -> 0 | O28: =IF(A28="","",IF(I28=0,"",IF(L28=0,"Meta cumplida",IF(WEEKDAY(A28,2)<=4,"En curso","Recuperando"))))
A29: =IF(23<=DAY(EOMONTH(DATE(Configuracion!$B$7,Configuracion!$B$8,1),0)),DATE(Configuracion!$B$7,Configuracion!$B$8,23),"") -> 46196 | B29: =IF(A29="","",CHOOSE(WEEKDAY(A29,2),"Lunes","Martes","Miercoles","Jueves","Viernes","Sabado","Domingo")) -> Martes | C29: =IF(A29="","",INT((DAY(A29)+WEEKDAY(DATE(YEAR(A29),MONTH(A29),1),2)-2)/7)+1) -> 4 | I29: =IF(A29="","",SUM(D29:H29)) -> 0 | J29: =IF(A29="","",IF(WEEKDAY(A29,2)<=4,Configuracion!$B$9,0)) -> 20 | K29: =IF(A29="","",IF(WEEKDAY(A29,2)<=4,Configuracion!$B$9,IF(SUMIFS($J$7:$J$37,$C$7:$C$37,C29)=0,0,ROUNDUP(MAX(0,SUMIFS($J$7:$J$37,$C$7:$C$37,C29)-SUMIFS($I$7:$I$37,$C$7:$C$37,C29,$A$7:$A$37,"<"&A29))/(8-WEEKDAY(A29,2)),0)))) -> 20 | L29: =IF(A29="","",MAX(0,SUMIFS($J$7:$J$37,$C$7:$C$37,C29)-SUMIFS($I$7:$I$37,$C$7:$C$37,C29,$A$7:$A$37,"<="&A29))) -> 80 | M29: =IF(A29="","",D29*Configuracion!$B$14+E29*Configuracion!$B$15+F29*Configuracion!$B$16+G29*Configuracion!$B$17+H29*Configuracion!$B$18) -> 0 | N29: =IF(A29="","",M29*Configuracion!$B$10) -> 0 | O29: =IF(A29="","",IF(I29=0,"",IF(L29=0,"Meta cumplida",IF(WEEKDAY(A29,2)<=4,"En curso","Recuperando"))))
A30: =IF(24<=DAY(EOMONTH(DATE(Configuracion!$B$7,Configuracion!$B$8,1),0)),DATE(Configuracion!$B$7,Configuracion!$B$8,24),"") -> 46197 | B30: =IF(A30="","",CHOOSE(WEEKDAY(A30,2),"Lunes","Martes","Miercoles","Jueves","Viernes","Sabado","Domingo")) -> Miercoles | C30: =IF(A30="","",INT((DAY(A30)+WEEKDAY(DATE(YEAR(A30),MONTH(A30),1),2)-2)/7)+1) -> 4 | I30: =IF(A30="","",SUM(D30:H30)) -> 0 | J30: =IF(A30="","",IF(WEEKDAY(A30,2)<=4,Configuracion!$B$9,0)) -> 20 | K30: =IF(A30="","",IF(WEEKDAY(A30,2)<=4,Configuracion!$B$9,IF(SUMIFS($J$7:$J$37,$C$7:$C$37,C30)=0,0,ROUNDUP(MAX(0,SUMIFS($J$7:$J$37,$C$7:$C$37,C30)-SUMIFS($I$7:$I$37,$C$7:$C$37,C30,$A$7:$A$37,"<"&A30))/(8-WEEKDAY(A30,2)),0)))) -> 20 | L30: =IF(A30="","",MAX(0,SUMIFS($J$7:$J$37,$C$7:$C$37,C30)-SUMIFS($I$7:$I$37,$C$7:$C$37,C30,$A$7:$A$37,"<="&A30))) -> 80 | M30: =IF(A30="","",D30*Configuracion!$B$14+E30*Configuracion!$B$15+F30*Configuracion!$B$16+G30*Configuracion!$B$17+H30*Configuracion!$B$18) -> 0 | N30: =IF(A30="","",M30*Configuracion!$B$10) -> 0 | O30: =IF(A30="","",IF(I30=0,"",IF(L30=0,"Meta cumplida",IF(WEEKDAY(A30,2)<=4,"En curso","Recuperando"))))
A31: =IF(25<=DAY(EOMONTH(DATE(Configuracion!$B$7,Configuracion!$B$8,1),0)),DATE(Configuracion!$B$7,Configuracion!$B$8,25),"") -> 46198 | B31: =IF(A31="","",CHOOSE(WEEKDAY(A31,2),"Lunes","Martes","Miercoles","Jueves","Viernes","Sabado","Domingo")) -> Jueves | C31: =IF(A31="","",INT((DAY(A31)+WEEKDAY(DATE(YEAR(A31),MONTH(A31),1),2)-2)/7)+1) -> 4 | I31: =IF(A31="","",SUM(D31:H31)) -> 0 | J31: =IF(A31="","",IF(WEEKDAY(A31,2)<=4,Configuracion!$B$9,0)) -> 20 | K31: =IF(A31="","",IF(WEEKDAY(A31,2)<=4,Configuracion!$B$9,IF(SUMIFS($J$7:$J$37,$C$7:$C$37,C31)=0,0,ROUNDUP(MAX(0,SUMIFS($J$7:$J$37,$C$7:$C$37,C31)-SUMIFS($I$7:$I$37,$C$7:$C$37,C31,$A$7:$A$37,"<"&A31))/(8-WEEKDAY(A31,2)),0)))) -> 20 | L31: =IF(A31="","",MAX(0,SUMIFS($J$7:$J$37,$C$7:$C$37,C31)-SUMIFS($I$7:$I$37,$C$7:$C$37,C31,$A$7:$A$37,"<="&A31))) -> 80 | M31: =IF(A31="","",D31*Configuracion!$B$14+E31*Configuracion!$B$15+F31*Configuracion!$B$16+G31*Configuracion!$B$17+H31*Configuracion!$B$18) -> 0 | N31: =IF(A31="","",M31*Configuracion!$B$10) -> 0 | O31: =IF(A31="","",IF(I31=0,"",IF(L31=0,"Meta cumplida",IF(WEEKDAY(A31,2)<=4,"En curso","Recuperando"))))
A32: =IF(26<=DAY(EOMONTH(DATE(Configuracion!$B$7,Configuracion!$B$8,1),0)),DATE(Configuracion!$B$7,Configuracion!$B$8,26),"") -> 46199 | B32: =IF(A32="","",CHOOSE(WEEKDAY(A32,2),"Lunes","Martes","Miercoles","Jueves","Viernes","Sabado","Domingo")) -> Viernes | C32: =IF(A32="","",INT((DAY(A32)+WEEKDAY(DATE(YEAR(A32),MONTH(A32),1),2)-2)/7)+1) -> 4 | I32: =IF(A32="","",SUM(D32:H32)) -> 0 | J32: =IF(A32="","",IF(WEEKDAY(A32,2)<=4,Configuracion!$B$9,0)) -> 0 | K32: =IF(A32="","",IF(WEEKDAY(A32,2)<=4,Configuracion!$B$9,IF(SUMIFS($J$7:$J$37,$C$7:$C$37,C32)=0,0,ROUNDUP(MAX(0,SUMIFS($J$7:$J$37,$C$7:$C$37,C32)-SUMIFS($I$7:$I$37,$C$7:$C$37,C32,$A$7:$A$37,"<"&A32))/(8-WEEKDAY(A32,2)),0)))) -> 27 | L32: =IF(A32="","",MAX(0,SUMIFS($J$7:$J$37,$C$7:$C$37,C32)-SUMIFS($I$7:$I$37,$C$7:$C$37,C32,$A$7:$A$37,"<="&A32))) -> 80 | M32: =IF(A32="","",D32*Configuracion!$B$14+E32*Configuracion!$B$15+F32*Configuracion!$B$16+G32*Configuracion!$B$17+H32*Configuracion!$B$18) -> 0 | N32: =IF(A32="","",M32*Configuracion!$B$10) -> 0 | O32: =IF(A32="","",IF(I32=0,"",IF(L32=0,"Meta cumplida",IF(WEEKDAY(A32,2)<=4,"En curso","Recuperando"))))
A33: =IF(27<=DAY(EOMONTH(DATE(Configuracion!$B$7,Configuracion!$B$8,1),0)),DATE(Configuracion!$B$7,Configuracion!$B$8,27),"") -> 46200 | B33: =IF(A33="","",CHOOSE(WEEKDAY(A33,2),"Lunes","Martes","Miercoles","Jueves","Viernes","Sabado","Domingo")) -> Sabado | C33: =IF(A33="","",INT((DAY(A33)+WEEKDAY(DATE(YEAR(A33),MONTH(A33),1),2)-2)/7)+1) -> 4 | I33: =IF(A33="","",SUM(D33:H33)) -> 0 | J33: =IF(A33="","",IF(WEEKDAY(A33,2)<=4,Configuracion!$B$9,0)) -> 0 | K33: =IF(A33="","",IF(WEEKDAY(A33,2)<=4,Configuracion!$B$9,IF(SUMIFS($J$7:$J$37,$C$7:$C$37,C33)=0,0,ROUNDUP(MAX(0,SUMIFS($J$7:$J$37,$C$7:$C$37,C33)-SUMIFS($I$7:$I$37,$C$7:$C$37,C33,$A$7:$A$37,"<"&A33))/(8-WEEKDAY(A33,2)),0)))) -> 40 | L33: =IF(A33="","",MAX(0,SUMIFS($J$7:$J$37,$C$7:$C$37,C33)-SUMIFS($I$7:$I$37,$C$7:$C$37,C33,$A$7:$A$37,"<="&A33))) -> 80 | M33: =IF(A33="","",D33*Configuracion!$B$14+E33*Configuracion!$B$15+F33*Configuracion!$B$16+G33*Configuracion!$B$17+H33*Configuracion!$B$18) -> 0 | N33: =IF(A33="","",M33*Configuracion!$B$10) -> 0 | O33: =IF(A33="","",IF(I33=0,"",IF(L33=0,"Meta cumplida",IF(WEEKDAY(A33,2)<=4,"En curso","Recuperando"))))
A34: =IF(28<=DAY(EOMONTH(DATE(Configuracion!$B$7,Configuracion!$B$8,1),0)),DATE(Configuracion!$B$7,Configuracion!$B$8,28),"") -> 46201 | B34: =IF(A34="","",CHOOSE(WEEKDAY(A34,2),"Lunes","Martes","Miercoles","Jueves","Viernes","Sabado","Domingo")) -> Domingo | C34: =IF(A34="","",INT((DAY(A34)+WEEKDAY(DATE(YEAR(A34),MONTH(A34),1),2)-2)/7)+1) -> 4 | I34: =IF(A34="","",SUM(D34:H34)) -> 0 | J34: =IF(A34="","",IF(WEEKDAY(A34,2)<=4,Configuracion!$B$9,0)) -> 0 | K34: =IF(A34="","",IF(WEEKDAY(A34,2)<=4,Configuracion!$B$9,IF(SUMIFS($J$7:$J$37,$C$7:$C$37,C34)=0,0,ROUNDUP(MAX(0,SUMIFS($J$7:$J$37,$C$7:$C$37,C34)-SUMIFS($I$7:$I$37,$C$7:$C$37,C34,$A$7:$A$37,"<"&A34))/(8-WEEKDAY(A34,2)),0)))) -> 80 | L34: =IF(A34="","",MAX(0,SUMIFS($J$7:$J$37,$C$7:$C$37,C34)-SUMIFS($I$7:$I$37,$C$7:$C$37,C34,$A$7:$A$37,"<="&A34))) -> 80 | M34: =IF(A34="","",D34*Configuracion!$B$14+E34*Configuracion!$B$15+F34*Configuracion!$B$16+G34*Configuracion!$B$17+H34*Configuracion!$B$18) -> 0 | N34: =IF(A34="","",M34*Configuracion!$B$10) -> 0 | O34: =IF(A34="","",IF(I34=0,"",IF(L34=0,"Meta cumplida",IF(WEEKDAY(A34,2)<=4,"En curso","Recuperando"))))
A35: =IF(29<=DAY(EOMONTH(DATE(Configuracion!$B$7,Configuracion!$B$8,1),0)),DATE(Configuracion!$B$7,Configuracion!$B$8,29),"") -> 46202 | B35: =IF(A35="","",CHOOSE(WEEKDAY(A35,2),"Lunes","Martes","Miercoles","Jueves","Viernes","Sabado","Domingo")) -> Lunes | C35: =IF(A35="","",INT((DAY(A35)+WEEKDAY(DATE(YEAR(A35),MONTH(A35),1),2)-2)/7)+1) -> 5 | I35: =IF(A35="","",SUM(D35:H35)) -> 0 | J35: =IF(A35="","",IF(WEEKDAY(A35,2)<=4,Configuracion!$B$9,0)) -> 20 | K35: =IF(A35="","",IF(WEEKDAY(A35,2)<=4,Configuracion!$B$9,IF(SUMIFS($J$7:$J$37,$C$7:$C$37,C35)=0,0,ROUNDUP(MAX(0,SUMIFS($J$7:$J$37,$C$7:$C$37,C35)-SUMIFS($I$7:$I$37,$C$7:$C$37,C35,$A$7:$A$37,"<"&A35))/(8-WEEKDAY(A35,2)),0)))) -> 20 | L35: =IF(A35="","",MAX(0,SUMIFS($J$7:$J$37,$C$7:$C$37,C35)-SUMIFS($I$7:$I$37,$C$7:$C$37,C35,$A$7:$A$37,"<="&A35))) -> 40 | M35: =IF(A35="","",D35*Configuracion!$B$14+E35*Configuracion!$B$15+F35*Configuracion!$B$16+G35*Configuracion!$B$17+H35*Configuracion!$B$18) -> 0 | N35: =IF(A35="","",M35*Configuracion!$B$10) -> 0 | O35: =IF(A35="","",IF(I35=0,"",IF(L35=0,"Meta cumplida",IF(WEEKDAY(A35,2)<=4,"En curso","Recuperando"))))
A36: =IF(30<=DAY(EOMONTH(DATE(Configuracion!$B$7,Configuracion!$B$8,1),0)),DATE(Configuracion!$B$7,Configuracion!$B$8,30),"") -> 46203 | B36: =IF(A36="","",CHOOSE(WEEKDAY(A36,2),"Lunes","Martes","Miercoles","Jueves","Viernes","Sabado","Domingo")) -> Martes | C36: =IF(A36="","",INT((DAY(A36)+WEEKDAY(DATE(YEAR(A36),MONTH(A36),1),2)-2)/7)+1) -> 5 | I36: =IF(A36="","",SUM(D36:H36)) -> 0 | J36: =IF(A36="","",IF(WEEKDAY(A36,2)<=4,Configuracion!$B$9,0)) -> 20 | K36: =IF(A36="","",IF(WEEKDAY(A36,2)<=4,Configuracion!$B$9,IF(SUMIFS($J$7:$J$37,$C$7:$C$37,C36)=0,0,ROUNDUP(MAX(0,SUMIFS($J$7:$J$37,$C$7:$C$37,C36)-SUMIFS($I$7:$I$37,$C$7:$C$37,C36,$A$7:$A$37,"<"&A36))/(8-WEEKDAY(A36,2)),0)))) -> 20 | L36: =IF(A36="","",MAX(0,SUMIFS($J$7:$J$37,$C$7:$C$37,C36)-SUMIFS($I$7:$I$37,$C$7:$C$37,C36,$A$7:$A$37,"<="&A36))) -> 40 | M36: =IF(A36="","",D36*Configuracion!$B$14+E36*Configuracion!$B$15+F36*Configuracion!$B$16+G36*Configuracion!$B$17+H36*Configuracion!$B$18) -> 0 | N36: =IF(A36="","",M36*Configuracion!$B$10) -> 0 | O36: =IF(A36="","",IF(I36=0,"",IF(L36=0,"Meta cumplida",IF(WEEKDAY(A36,2)<=4,"En curso","Recuperando"))))
A37: =IF(31<=DAY(EOMONTH(DATE(Configuracion!$B$7,Configuracion!$B$8,1),0)),DATE(Configuracion!$B$7,Configuracion!$B$8,31),"") | B37: =IF(A37="","",CHOOSE(WEEKDAY(A37,2),"Lunes","Martes","Miercoles","Jueves","Viernes","Sabado","Domingo")) | C37: =IF(A37="","",INT((DAY(A37)+WEEKDAY(DATE(YEAR(A37),MONTH(A37),1),2)-2)/7)+1) | I37: =IF(A37="","",SUM(D37:H37)) | J37: =IF(A37="","",IF(WEEKDAY(A37,2)<=4,Configuracion!$B$9,0)) | K37: =IF(A37="","",IF(WEEKDAY(A37,2)<=4,Configuracion!$B$9,IF(SUMIFS($J$7:$J$37,$C$7:$C$37,C37)=0,0,ROUNDUP(MAX(0,SUMIFS($J$7:$J$37,$C$7:$C$37,C37)-SUMIFS($I$7:$I$37,$C$7:$C$37,C37,$A$7:$A$37,"<"&A37))/(8-WEEKDAY(A37,2)),0)))) | L37: =IF(A37="","",MAX(0,SUMIFS($J$7:$J$37,$C$7:$C$37,C37)-SUMIFS($I$7:$I$37,$C$7:$C$37,C37,$A$7:$A$37,"<="&A37))) | M37: =IF(A37="","",D37*Configuracion!$B$14+E37*Configuracion!$B$15+F37*Configuracion!$B$16+G37*Configuracion!$B$17+H37*Configuracion!$B$18) | N37: =IF(A37="","",M37*Configuracion!$B$10) | O37: =IF(A37="","",IF(I37=0,"",IF(L37=0,"Meta cumplida",IF(WEEKDAY(A37,2)<=4,"En curso","Recuperando"))))

Sheet Gastos volqueta
A1: GASTOS DE LA VOLQUETA | B1: GASTOS DE LA VOLQUETA | C1: GASTOS DE LA VOLQUETA | D1: GASTOS DE LA VOLQUETA | E1: GASTOS DE LA VOLQUETA | F1: GASTOS DE LA VOLQUETA | G1: GASTOS DE LA VOLQUETA | H1: GASTOS DE LA VOLQUETA | I1: GASTOS DE LA VOLQUETA
A2: GASTOS DE LA VOLQUETA | B2: GASTOS DE LA VOLQUETA | C2: GASTOS DE LA VOLQUETA | D2: GASTOS DE LA VOLQUETA | E2: GASTOS DE LA VOLQUETA | F2: GASTOS DE LA VOLQUETA | G2: GASTOS DE LA VOLQUETA | H2: GASTOS DE LA VOLQUETA | I2: GASTOS DE LA VOLQUETA
A3: ="Periodo activo: "&CHOOSE(Configuracion!$B$8,"Enero","Febrero","Marzo","Abril","Mayo","Junio","Julio","Agosto","Septiembre","Octubre","Noviembre","Diciembre")&" "&Configuracion!$B$7&" | Anota aqui cada egreso." -> Periodo activo: Junio 2026 | Anota aqui cada egreso.
A5: Tip: usa una fila por factura, recibo, tanqueo, arreglo o gasto. El resumen toma solo el mes seleccionado en Configuracion. | B5: Tip: usa una fila por factura, recibo, tanqueo, arreglo o gasto. El resumen toma solo el mes seleccionado en Configuracion. | C5: Tip: usa una fila por factura, recibo, tanqueo, arreglo o gasto. El resumen toma solo el mes seleccionado en Configuracion. | D5: Tip: usa una fila por factura, recibo, tanqueo, arreglo o gasto. El resumen toma solo el mes seleccionado en Configuracion. | E5: Tip: usa una fila por factura, recibo, tanqueo, arreglo o gasto. El resumen toma solo el mes seleccionado en Configuracion. | F5: Tip: usa una fila por factura, recibo, tanqueo, arreglo o gasto. El resumen toma solo el mes seleccionado en Configuracion. | G5: Tip: usa una fila por factura, recibo, tanqueo, arreglo o gasto. El resumen toma solo el mes seleccionado en Configuracion. | H5: Tip: usa una fila por factura, recibo, tanqueo, arreglo o gasto. El resumen toma solo el mes seleccionado en Configuracion. | I5: Tip: usa una fila por factura, recibo, tanqueo, arreglo o gasto. El resumen toma solo el mes seleccionado en Configuracion.
A6: Fecha | B6: Mes | C6: Categoria | D6: Detalle | E6: Valor | F6: Pagado por | G6: Medio pago | H6: Observaciones | I6: Año
B7: =IF(A7="","",MONTH(A7)) | I7: =IF(A7="","",YEAR(A7))
B8: =IF(A8="","",MONTH(A8)) | I8: =IF(A8="","",YEAR(A8))
B9: =IF(A9="","",MONTH(A9)) | I9: =IF(A9="","",YEAR(A9))
B10: =IF(A10="","",MONTH(A10)) | I10: =IF(A10="","",YEAR(A10))
B11: =IF(A11="","",MONTH(A11)) | I11: =IF(A11="","",YEAR(A11))
B12: =IF(A12="","",MONTH(A12)) | I12: =IF(A12="","",YEAR(A12))
B13: =IF(A13="","",MONTH(A13)) | I13: =IF(A13="","",YEAR(A13))
B14: =IF(A14="","",MONTH(A14)) | I14: =IF(A14="","",YEAR(A14))
B15: =IF(A15="","",MONTH(A15)) | I15: =IF(A15="","",YEAR(A15))
B16: =IF(A16="","",MONTH(A16)) | I16: =IF(A16="","",YEAR(A16))
B17: =IF(A17="","",MONTH(A17)) | I17: =IF(A17="","",YEAR(A17))
B18: =IF(A18="","",MONTH(A18)) | I18: =IF(A18="","",YEAR(A18))
... B205: =IF(A205="","",MONTH(A205)) | I205: =IF(A205="","",YEAR(A205))

Sheet Aportes tios
A1: APORTES / ENVIOS DE TIOS | B1: APORTES / ENVIOS DE TIOS | C1: APORTES / ENVIOS DE TIOS | D1: APORTES / ENVIOS DE TIOS | E1: APORTES / ENVIOS DE TIOS | F1: APORTES / ENVIOS DE TIOS | G1: APORTES / ENVIOS DE TIOS | H1: APORTES / ENVIOS DE TIOS
A2: APORTES / ENVIOS DE TIOS | B2: APORTES / ENVIOS DE TIOS | C2: APORTES / ENVIOS DE TIOS | D2: APORTES / ENVIOS DE TIOS | E2: APORTES / ENVIOS DE TIOS | F2: APORTES / ENVIOS DE TIOS | G2: APORTES / ENVIOS DE TIOS | H2: APORTES / ENVIOS DE TIOS
A3: ="Periodo activo: "&CHOOSE(Configuracion!$B$8,"Enero","Febrero","Marzo","Abril","Mayo","Junio","Julio","Agosto","Septiembre","Octubre","Noviembre","Diciembre")&" "&Configuracion!$B$7&" | Anota aqui cada envio recibido." -> Periodo activo: Junio 2026 | Anota aqui cada envio recibido.
A5: El resumen compara lo que deberia enviar cada tio contra lo que realmente envio en este mes. | B5: El resumen compara lo que deberia enviar cada tio contra lo que realmente envio en este mes. | C5: El resumen compara lo que deberia enviar cada tio contra lo que realmente envio en este mes. | D5: El resumen compara lo que deberia enviar cada tio contra lo que realmente envio en este mes. | E5: El resumen compara lo que deberia enviar cada tio contra lo que realmente envio en este mes. | F5: El resumen compara lo que deberia enviar cada tio contra lo que realmente envio en este mes. | G5: El resumen compara lo que deberia enviar cada tio contra lo que realmente envio en este mes. | H5: El resumen compara lo que deberia enviar cada tio contra lo que realmente envio en este mes.
A6: Fecha | B6: Mes | C6: Tio | D6: Concepto | E6: Valor enviado | F6: Medio envio | G6: Observaciones | H6: Año
B7: =IF(A7="","",MONTH(A7)) | H7: =IF(A7="","",YEAR(A7))
B8: =IF(A8="","",MONTH(A8)) | H8: =IF(A8="","",YEAR(A8))
B9: =IF(A9="","",MONTH(A9)) | H9: =IF(A9="","",YEAR(A9))
B10: =IF(A10="","",MONTH(A10)) | H10: =IF(A10="","",YEAR(A10))
B11: =IF(A11="","",MONTH(A11)) | H11: =IF(A11="","",YEAR(A11))
B12: =IF(A12="","",MONTH(A12)) | H12: =IF(A12="","",YEAR(A12))
B13: =IF(A13="","",MONTH(A13)) | H13: =IF(A13="","",YEAR(A13))
B14: =IF(A14="","",MONTH(A14)) | H14: =IF(A14="","",YEAR(A14))
B15: =IF(A15="","",MONTH(A15)) | H15: =IF(A15="","",YEAR(A15))
B16: =IF(A16="","",MONTH(A16)) | H16: =IF(A16="","",YEAR(A16))
B17: =IF(A17="","",MONTH(A17)) | H17: =IF(A17="","",YEAR(A17))
B18: =IF(A18="","",MONTH(A18)) | H18: =IF(A18="","",YEAR(A18))
... B205: =IF(A205="","",MONTH(A205)) | H205: =IF(A205="","",YEAR(A205))

Sheet Configuracion
A1: CONFIGURACION - CONTROL DE VOLQUETAS | B1: CONFIGURACION - CONTROL DE VOLQUETAS | C1: CONFIGURACION - CONTROL DE VOLQUETAS | D1: CONFIGURACION - CONTROL DE VOLQUETAS | E1: CONFIGURACION - CONTROL DE VOLQUETAS | F1: CONFIGURACION - CONTROL DE VOLQUETAS | G1: CONFIGURACION - CONTROL DE VOLQUETAS | H1: CONFIGURACION - CONTROL DE VOLQUETAS | I1: CONFIGURACION - CONTROL DE VOLQUETAS
A2: CONFIGURACION - CONTROL DE VOLQUETAS | B2: CONFIGURACION - CONTROL DE VOLQUETAS | C2: CONFIGURACION - CONTROL DE VOLQUETAS | D2: CONFIGURACION - CONTROL DE VOLQUETAS | E2: CONFIGURACION - CONTROL DE VOLQUETAS | F2: CONFIGURACION - CONTROL DE VOLQUETAS | G2: CONFIGURACION - CONTROL DE VOLQUETAS | H2: CONFIGURACION - CONTROL DE VOLQUETAS | I2: CONFIGURACION - CONTROL DE VOLQUETAS
A3: Cambia solamente las celdas amarillas con letra azul. El resto del archivo se actualiza automaticamente. | B3: Cambia solamente las celdas amarillas con letra azul. El resto del archivo se actualiza automaticamente. | C3: Cambia solamente las celdas amarillas con letra azul. El resto del archivo se actualiza automaticamente. | D3: Cambia solamente las celdas amarillas con letra azul. El resto del archivo se actualiza automaticamente. | E3: Cambia solamente las celdas amarillas con letra azul. El resto del archivo se actualiza automaticamente. | F3: Cambia solamente las celdas amarillas con letra azul. El resto del archivo se actualiza automaticamente. | G3: Cambia solamente las celdas amarillas con letra azul. El resto del archivo se actualiza automaticamente. | H3: Cambia solamente las celdas amarillas con letra azul. El resto del archivo se actualiza automaticamente. | I3: Cambia solamente las celdas amarillas con letra azul. El resto del archivo se actualiza automaticamente.
A5: PARAMETROS DEL MES | B5: PARAMETROS DEL MES | C5: PARAMETROS DEL MES | G5: LISTAS EDITABLES | H5: LISTAS EDITABLES | I5: LISTAS EDITABLES
A6: Parametro | B6: Valor | G6: Categoria gasto | H6: Pagado por | I6: Medio pago/envio
A7: Año | B7: 2026 | G7: ACPM | H7: Mi bolsillo | I7: Nequi
A8: Mes (1 a 12) | B8: 6 | G8: Mantenimiento | H8: Juancho | I8: Daviplata
A9: Meta diaria lunes a jueves | B9: 20 | G9: Llantas | H9: Beto | I9: Davivienda
A10: Porcentaje para mi | B10: 0.22 | G10: Aceite | H10: Caja | I10: Bancolombia
G11: Lavadero | H11: Otro | I11: Efectivo
A12: TARIFAS POR VIAJE | B12: TARIFAS POR VIAJE | C12: TARIFAS POR VIAJE | D12: TARIFAS POR VIAJE | G12: Peajes | I12: Transferencia
A13: Ruta | B13: Tarifa | C13: Nota | G13: Parqueadero | I13: Banco
A14: Rio a trituradora | B14: 32000 | C14: Valor segun relacion de viajes | G14: Reparacion | I14: Otro
A15: Rio a stock | B15: 30000 | C15: Valor por cada viaje | G15: Alimentacion
A16: Stock a trituradora | B16: 16000 | C16: Stock/STOP a trituradora | G16: Documentos
A17: Trituradora a stock | B17: 12000 | C17: Trituradora a stock/STOP | G17: Impuestos
A18: Stock a stock | B18: 12000 | C18: Stock/STOP a stock/STOP | G18: Seguro
G19: Multas
A20: REPARTO DE GASTOS ENTRE TIOS | B20: REPARTO DE GASTOS ENTRE TIOS | C20: REPARTO DE GASTOS ENTRE TIOS | D20: REPARTO DE GASTOS ENTRE TIOS | G20: Grua
A21: Persona | B21: % que cubre | C21: Nota | G21: Lavada
A22: Juancho | B22: 0.5 | C22: Editable | G22: Repuestos
A23: Beto | B23: 0.5 | C23: Editable | G23: Mano de obra
A24: Total reparto | B24: =SUM(B22:B23) -> 1 | G24: Prestamo
G25: Otro
A26: COMO USAR EL ARCHIVO | B26: COMO USAR EL ARCHIVO | C26: COMO USAR EL ARCHIVO | D26: COMO USAR EL ARCHIVO | E26: COMO USAR EL ARCHIVO | F26: COMO USAR EL ARCHIVO
A27: 1. Selecciona el año y el mes en esta hoja.
A28: 2. En Registro diario escribe la cantidad de viajes de cada ruta.
A29: 3. En Gastos volqueta anota cada egreso con fecha, categoria y valor.
A30: 4. En Aportes tios anota lo que envien Juancho y Beto.
A31: 5. El resumen calcula ingresos, gastos, saldos pendientes y lo que falta por enviar.
A32: 6. La meta normal es de lunes a jueves; el atraso se reparte entre viernes, sabado y domingo.
